<?xml version='1.0'?>

<robot name="mogi_bot" xmlns:xacro="http://www.ros.org/wiki/xacro">

  <!-- STEP 3 - Gazebo plugin -->
  <xacro:include filename="$(find kinclong_nav)/urdf/mogi_bot.gazebo" />

  <!-- STEP 4 - RViz colors -->
  <xacro:include filename="$(find kinclong_nav)/urdf/materials.xacro" />

  <!-- STEP 1 - Robot chassis -->
  <link name="base_footprint"></link>

  <joint name="base_footprint_joint" type="fixed">
    <origin xyz="0 0 0" rpy="0 0 -1.5707" />
    <parent link="base_footprint"/>
    <child link="base_link" />
  </joint>

  <link name='base_link'>

    <inertial>
      <mass value="2.0"/>
      <origin xyz="0 0 0" rpy=" 0 0 0"/>
      <inertia
          ixx="0.0625" ixy="0" ixz="0"
          iyy="0.2125" iyz="0"
          izz="0.25"
      />
    </inertial>

    <collision name='collision'>
      <origin xyz="0 0 0.048" rpy=" 0 0 0"/> 
      <geometry>
        <cylinder radius="0.2" length="0.1"/>
      </geometry>
    </collision>

    <visual name="base_link_visual">
      <origin xyz="0 0 0" rpy="0 0 0"/>
      <geometry>
        <mesh filename="package://kinclong_nav/meshes/body.stl"/>
      </geometry>
      <material name="red"/>
    </visual>

<!-- 
    <collision name='rear_caster_collision'>
      <origin xyz="0 -0.17 0" rpy=" 0 0 0"/>
      <geometry>
        <sphere radius="0.088"/>
      </geometry>
    </collision>

    <visual name='rear_caster_visual'>
      <origin xyz="0 -0.17 0" rpy=" 0 0 0"/>
      <geometry>
        <sphere radius="0.008"/>
      </geometry>
    </visual>

    <collision name='front_caster_collision'>
      <origin xyz="0.15 0 -0.05" rpy=" 0 0 0"/>
      <geometry>
        <sphere radius="0.015"/>
      </geometry>
    </collision>

    <visual name='front_caster_visual'>
      <origin xyz="0.15 0 -0.05" rpy=" 0 0 0"/>
      <geometry>
        <sphere radius="0.015"/>
      </geometry>
    </visual> -->

  </link>

  <!-- STEP 2 - Wheels -->
  <joint type="continuous" name="left_wheel_joint">
      <parent link="base_link"/>
      <child link="left_wheel"/>
      <origin xyz="-0.142 0 0.03" rpy="0 0 0 "/>
      <axis xyz="-1 0 0"/>
      <limit effort="100" velocity="10.0"/>
      <dynamics damping="1.0" friction="1.0"/>
  </joint>

  <link name='left_wheel'>
    <inertial>
      <mass value="0.3"/>
      <origin xyz="0 0 0" rpy="0 1.5707 0"/> 
      <inertia
          ixx="0.014" ixy="0" ixz="0"
          iyy="0.014" iyz="0"
          izz="0.025"
      />
    </inertial>

    <collision>
    <origin xyz="0 0 0" rpy="0 1.5707 0"/> 
        <geometry>
          <cylinder radius="0.0325" length="0.025"/>
        </geometry>
    </collision>

    <visual name='left_wheel_visual'>
    <origin xyz="0 0 0" rpy="0 1.5707 0"/> 
      <geometry>
        <mesh filename = "package://kinclong_nav/meshes/roda.stl"/>
      </geometry>
      <material name="black"/>
    </visual>
  </link>

  <joint type="continuous" name="right_wheel_joint">
    <parent link="base_link"/>
    <child link="right_wheel"/>
    <origin xyz="0.142 0 0.03" rpy="0 0 0"/> 
    <axis xyz="-1 0 0"/>
    <limit effort="100" velocity="10.0"/>
    <dynamics damping="1.0" friction="1.0"/>
  </joint>

  <link name='right_wheel'>
    <inertial>
      <mass value="0.3"/>
      <origin xyz="0 0 0" rpy="0 1.5707 3.1416"/>
      <inertia
          ixx="0.014" ixy="0" ixz="0"
          iyy="0.014" iyz="0"
          izz="0.025"
      />
       
    </inertial>

    <collision>
    <origin xyz="0 0 0" rpy="0 1.5707	3.1416"/>
        <geometry>
          <cylinder radius="0.0325" length="0.025"/>
        </geometry>
    </collision>

    <visual name='right_wheel_visual'>
    <origin xyz="0 0 0" rpy="0 1.5707 3.1416"/>
      <geometry>
        <mesh filename = "package://kinclong_nav/meshes/roda.stl"/>
      </geometry>
      <material name="black"/>
    </visual>
  </link>

  <!-- STEP 4 - Gazebo frictions and colors -->
  <gazebo reference="left_wheel">
    <mu1>0.2</mu1>
    <mu2>0.2</mu2>
    <kp>1000000.0</kp>
    <kd>100.0</kd>
    <minDepth>0.0001</minDepth>
    <maxVel>1.0</maxVel>
  </gazebo>

  <gazebo reference="right_wheel">
    <mu1>0.2</mu1>
    <mu2>0.2</mu2>
    <kp>1000000.0</kp>
    <kd>100.0</kd>
    <minDepth>0.0001</minDepth>
    <maxVel>1.0</maxVel>
  </gazebo>

  <gazebo reference="base_link">
    <mu1>0.000002</mu1>
    <mu2>0.000002</mu2>
  </gazebo>

  <!-- Lidar -->
  <joint type="fixed" name="scan_joint">
    <origin xyz="0 0.09 0.12" rpy="0 0 0"/>
    <child link="scan_link"/>
    <parent link="base_link"/>
    <axis xyz="0 1 0" rpy="0 0 0"/>
  </joint>

  <link name='scan_link'>
    <inertial>
      <mass value="1e-5"/>
      <origin xyz="0 0 0" rpy="0 0 0"/>
      <inertia
          ixx="1e-6" ixy="0" ixz="0"
          iyy="1e-6" iyz="0"
          izz="1e-6"
      />
    </inertial>
    <collision name='collision'>
      <origin xyz="0 0 -0.05" rpy="0 0 1.5707"/> 
      <geometry>
        <box size=".1 .1 .1"/>
      </geometry>
    </collision>

    <visual name='scan_link_visual'>
      <origin xyz="0 0 -0.05" rpy="0 0 1.5707"/>
      <geometry>
        <mesh filename = "package://kinclong_nav/meshes/lidar.stl"/>
      </geometry>
      <material name="black"/>
    </visual>

  </link>

  <gazebo reference="scan_link">
    <selfCollide>false</selfCollide>
    <mu1 value="0.05" />
    <mu2 value="0.05" />
  </gazebo>

</robot>